[ERROR][2022-08-10 12:52:40,481][command_client_1,pid:12046,tid:140236679259904][client.py:96.sync_send] - Error calling to 192.168.222.129:36223, command_uri: CommandURI(_uri=v1/egg-pair/runTask), req:ErCommandRequest(id=20220810.125240.465820, uri=v1/egg-pair/runTask, args=[[b'\naer_session_py_20220810.125209.732_192.168.222.129-py-job-20220810.125240.464968_withStores-task-0\x12\nwithStores\x1a\xbc\x01\x12p\x12\x0fROLL_PAIR_CACHE\x1a\x0fer_session_meta"1er_session_py_20220810.125209.732_192.168.222.1290\x03:\x0fBYTESTRING_HASHB\x06PICKLE\x1aH\x08\x04\x10\x02"\x08egg_pair*\x07RUNNING2\x15\n\x0f192.168.222.129\x10\xff\x9a\x02:\x15\n\x0f192.168.222.129\x10\xb5\xac\x02H'], len=1], kwargs=[***, len=0])
Traceback (most recent call last):
  File "/home/app/workspace/Eggroll_deploy_0/python/eggroll/core/client.py", line 84, in sync_send
    response = _command_stub.call(request.to_proto())
  File "/home/app/.venv_eggroll/lib/python3.6/site-packages/grpc/_channel.py", line 604, in __call__
    return _end_unary_response_blocking(state, call, False, None)
  File "/home/app/.venv_eggroll/lib/python3.6/site-packages/grpc/_channel.py", line 506, in _end_unary_response_blocking
    raise _Rendezvous(state, None, None, deadline)
grpc._channel._Rendezvous: <_Rendezvous of RPC that terminated with:
	status = StatusCode.UNKNOWN
	details = "Exception calling application: 

==== detail start, at 20220810.125240.480 ====
Traceback (most recent call last):
  File "/home/app/workspace/Eggroll_deploy_0/python/eggroll/core/utils.py", line 187, in wrapper
    return func(*args, **kw)
  File "/home/app/workspace/Eggroll_deploy_0/python/eggroll/roll_pair/egg_pair.py", line 690, in run_task
    value=self.functor_serdes.serialize(f(task)))
  File "/home/app/workspace/Eggroll_deploy_0/python/eggroll/roll_pair/test/test_roll_pair.py", line 80, in get_eggs
    eggs = input_adapter.get('eggs')
  File "/home/app/workspace/Eggroll_deploy_0/python/eggroll/core/pair_store/adapter.py", line 190, in get
    return self.data[key]
KeyError: 'eggs'

During handling of the above exception, another exception occurred:

Traceback (most recent call last):
  File "/home/app/workspace/Eggroll_deploy_0/python/eggroll/core/utils.py", line 187, in wrapper
    return func(*args, **kw)
  File "/home/app/workspace/Eggroll_deploy_0/python/eggroll/core/command/command_service.py", line 33, in call
    kwargs=getattr(command_request, '_kwargs'))
  File "/home/app/workspace/Eggroll_deploy_0/python/eggroll/core/command/command_router.py", line 94, in dispatch
    raise e
  File "/home/app/workspace/Eggroll_deploy_0/python/eggroll/core/command/command_router.py", line 91, in dispatch
    call_result = _method(_instance, *deserialized_args)
  File "/home/app/workspace/Eggroll_deploy_0/python/eggroll/core/utils.py", line 194, in wrapper
    raise RuntimeError(msg)
RuntimeError: 

==== detail start, at 20220810.125240.477 ====
Traceback (most recent call last):
  File "/home/app/workspace/Eggroll_deploy_0/python/eggroll/core/utils.py", line 187, in wrapper
    return func(*args, **kw)
  File "/home/app/workspace/Eggroll_deploy_0/python/eggroll/roll_pair/egg_pair.py", line 690, in run_task
    value=self.functor_serdes.serialize(f(task)))
  File "/home/app/workspace/Eggroll_deploy_0/python/eggroll/roll_pair/test/test_roll_pair.py", line 80, in get_eggs
    eggs = input_adapter.get('eggs')
  File "/home/app/workspace/Eggroll_deploy_0/python/eggroll/core/pair_store/adapter.py", line 190, in get
    return self.data[key]
KeyError: 'eggs'

==== detail end ====



==== detail end ====

"
	debug_error_string = "{"created":"@1660107160.480984702","description":"Error received from peer ipv4:192.168.222.129:36223","file":"src/core/lib/surface/call.cc","file_line":1055,"grpc_message":"Exception calling application: \n\n==== detail start, at 20220810.125240.480 ====\nTraceback (most recent call last):\n  File "/home/app/workspace/Eggroll_deploy_0/python/eggroll/core/utils.py", line 187, in wrapper\n    return func(*args, **kw)\n  File "/home/app/workspace/Eggroll_deploy_0/python/eggroll/roll_pair/egg_pair.py", line 690, in run_task\n    value=self.functor_serdes.serialize(f(task)))\n  File "/home/app/workspace/Eggroll_deploy_0/python/eggroll/roll_pair/test/test_roll_pair.py", line 80, in get_eggs\n    eggs = input_adapter.get('eggs')\n  File "/home/app/workspace/Eggroll_deploy_0/python/eggroll/core/pair_store/adapter.py", line 190, in get\n    return self.data[key]\nKeyError: 'eggs'\n\nDuring handling of the above exception, another exception occurred:\n\nTraceback (most recent call last):\n  File "/home/app/workspace/Eggroll_deploy_0/python/eggroll/core/utils.py", line 187, in wrapper\n    return func(*args, **kw)\n  File "/home/app/workspace/Eggroll_deploy_0/python/eggroll/core/command/command_service.py", line 33, in call\n    kwargs=getattr(command_request, '_kwargs'))\n  File "/home/app/workspace/Eggroll_deploy_0/python/eggroll/core/command/command_router.py", line 94, in dispatch\n    raise e\n  File "/home/app/workspace/Eggroll_deploy_0/python/eggroll/core/command/command_router.py", line 91, in dispatch\n    call_result = _method(_instance, *deserialized_args)\n  File "/home/app/workspace/Eggroll_deploy_0/python/eggroll/core/utils.py", line 194, in wrapper\n    raise RuntimeError(msg)\nRuntimeError: \n\n==== detail start, at 20220810.125240.477 ====\nTraceback (most recent call last):\n  File "/home/app/workspace/Eggroll_deploy_0/python/eggroll/core/utils.py", line 187, in wrapper\n    return func(*args, **kw)\n  File "/home/app/workspace/Eggroll_deploy_0/python/eggroll/roll_pair/egg_pair.py", line 690, in run_task\n    value=self.functor_serdes.serialize(f(task)))\n  File "/home/app/workspace/Eggroll_deploy_0/python/eggroll/roll_pair/test/test_roll_pair.py", line 80, in get_eggs\n    eggs = input_adapter.get('eggs')\n  File "/home/app/workspace/Eggroll_deploy_0/python/eggroll/core/pair_store/adapter.py", line 190, in get\n    return self.data[key]\nKeyError: 'eggs'\n\n==== detail end ====\n\n\n\n==== detail end ====\n\n","grpc_status":2}"
>
[ERROR][2022-08-10 12:52:40,482][command_client_2,pid:12046,tid:140236712830720][client.py:96.sync_send] - Error calling to 192.168.222.129:37735, command_uri: CommandURI(_uri=v1/egg-pair/runTask), req:ErCommandRequest(id=20220810.125240.468335, uri=v1/egg-pair/runTask, args=[[b'\naer_session_py_20220810.125209.732_192.168.222.129-py-job-20220810.125240.464968_withStores-task-1\x12\nwithStores\x1a\xc0\x01\x08\x01\x12p\x12\x0fROLL_PAIR_CACHE\x1a\x0fer_session_meta"1er_session_py_20220810.125209.732_192.168.222.1290\x03:\x0fBYTESTRING_HASHB\x06PICKLE\x1aH\x08\x05\x10\x02"\x08egg_pair*\x07RUNNING2\x15\n\x0f192.168.222.129\x10\xe7\xa6\x02:\x15\n\x0f192.168.222.129\x10\xab\xd3'], len=1], kwargs=[***, len=0])
Traceback (most recent call last):
  File "/home/app/workspace/Eggroll_deploy_0/python/eggroll/core/client.py", line 84, in sync_send
    response = _command_stub.call(request.to_proto())
  File "/home/app/.venv_eggroll/lib/python3.6/site-packages/grpc/_channel.py", line 604, in __call__
    return _end_unary_response_blocking(state, call, False, None)
  File "/home/app/.venv_eggroll/lib/python3.6/site-packages/grpc/_channel.py", line 506, in _end_unary_response_blocking
    raise _Rendezvous(state, None, None, deadline)
grpc._channel._Rendezvous: <_Rendezvous of RPC that terminated with:
	status = StatusCode.UNKNOWN
	details = "Exception calling application: 

==== detail start, at 20220810.125240.480 ====
Traceback (most recent call last):
  File "/home/app/workspace/Eggroll_deploy_0/python/eggroll/core/utils.py", line 187, in wrapper
    return func(*args, **kw)
  File "/home/app/workspace/Eggroll_deploy_0/python/eggroll/roll_pair/egg_pair.py", line 690, in run_task
    value=self.functor_serdes.serialize(f(task)))
  File "/home/app/workspace/Eggroll_deploy_0/python/eggroll/roll_pair/test/test_roll_pair.py", line 80, in get_eggs
    eggs = input_adapter.get('eggs')
  File "/home/app/workspace/Eggroll_deploy_0/python/eggroll/core/pair_store/adapter.py", line 190, in get
    return self.data[key]
KeyError: 'eggs'

During handling of the above exception, another exception occurred:

Traceback (most recent call last):
  File "/home/app/workspace/Eggroll_deploy_0/python/eggroll/core/utils.py", line 187, in wrapper
    return func(*args, **kw)
  File "/home/app/workspace/Eggroll_deploy_0/python/eggroll/core/command/command_service.py", line 33, in call
    kwargs=getattr(command_request, '_kwargs'))
  File "/home/app/workspace/Eggroll_deploy_0/python/eggroll/core/command/command_router.py", line 94, in dispatch
    raise e
  File "/home/app/workspace/Eggroll_deploy_0/python/eggroll/core/command/command_router.py", line 91, in dispatch
    call_result = _method(_instance, *deserialized_args)
  File "/home/app/workspace/Eggroll_deploy_0/python/eggroll/core/utils.py", line 194, in wrapper
    raise RuntimeError(msg)
RuntimeError: 

==== detail start, at 20220810.125240.479 ====
Traceback (most recent call last):
  File "/home/app/workspace/Eggroll_deploy_0/python/eggroll/core/utils.py", line 187, in wrapper
    return func(*args, **kw)
  File "/home/app/workspace/Eggroll_deploy_0/python/eggroll/roll_pair/egg_pair.py", line 690, in run_task
    value=self.functor_serdes.serialize(f(task)))
  File "/home/app/workspace/Eggroll_deploy_0/python/eggroll/roll_pair/test/test_roll_pair.py", line 80, in get_eggs
    eggs = input_adapter.get('eggs')
  File "/home/app/workspace/Eggroll_deploy_0/python/eggroll/core/pair_store/adapter.py", line 190, in get
    return self.data[key]
KeyError: 'eggs'

==== detail end ====



==== detail end ====

"
	debug_error_string = "{"created":"@1660107160.482163047","description":"Error received from peer ipv4:192.168.222.129:37735","file":"src/core/lib/surface/call.cc","file_line":1055,"grpc_message":"Exception calling application: \n\n==== detail start, at 20220810.125240.480 ====\nTraceback (most recent call last):\n  File "/home/app/workspace/Eggroll_deploy_0/python/eggroll/core/utils.py", line 187, in wrapper\n    return func(*args, **kw)\n  File "/home/app/workspace/Eggroll_deploy_0/python/eggroll/roll_pair/egg_pair.py", line 690, in run_task\n    value=self.functor_serdes.serialize(f(task)))\n  File "/home/app/workspace/Eggroll_deploy_0/python/eggroll/roll_pair/test/test_roll_pair.py", line 80, in get_eggs\n    eggs = input_adapter.get('eggs')\n  File "/home/app/workspace/Eggroll_deploy_0/python/eggroll/core/pair_store/adapter.py", line 190, in get\n    return self.data[key]\nKeyError: 'eggs'\n\nDuring handling of the above exception, another exception occurred:\n\nTraceback (most recent call last):\n  File "/home/app/workspace/Eggroll_deploy_0/python/eggroll/core/utils.py", line 187, in wrapper\n    return func(*args, **kw)\n  File "/home/app/workspace/Eggroll_deploy_0/python/eggroll/core/command/command_service.py", line 33, in call\n    kwargs=getattr(command_request, '_kwargs'))\n  File "/home/app/workspace/Eggroll_deploy_0/python/eggroll/core/command/command_router.py", line 94, in dispatch\n    raise e\n  File "/home/app/workspace/Eggroll_deploy_0/python/eggroll/core/command/command_router.py", line 91, in dispatch\n    call_result = _method(_instance, *deserialized_args)\n  File "/home/app/workspace/Eggroll_deploy_0/python/eggroll/core/utils.py", line 194, in wrapper\n    raise RuntimeError(msg)\nRuntimeError: \n\n==== detail start, at 20220810.125240.479 ====\nTraceback (most recent call last):\n  File "/home/app/workspace/Eggroll_deploy_0/python/eggroll/core/utils.py", line 187, in wrapper\n    return func(*args, **kw)\n  File "/home/app/workspace/Eggroll_deploy_0/python/eggroll/roll_pair/egg_pair.py", line 690, in run_task\n    value=self.functor_serdes.serialize(f(task)))\n  File "/home/app/workspace/Eggroll_deploy_0/python/eggroll/roll_pair/test/test_roll_pair.py", line 80, in get_eggs\n    eggs = input_adapter.get('eggs')\n  File "/home/app/workspace/Eggroll_deploy_0/python/eggroll/core/pair_store/adapter.py", line 190, in get\n    return self.data[key]\nKeyError: 'eggs'\n\n==== detail end ====\n\n\n\n==== detail end ====\n\n","grpc_status":2}"
>
[ERROR][2022-08-10 12:52:40,484][command_client_3,pid:12046,tid:140236687652608][client.py:96.sync_send] - Error calling to 192.168.222.129:34521, command_uri: CommandURI(_uri=v1/egg-pair/runTask), req:ErCommandRequest(id=20220810.125240.471494, uri=v1/egg-pair/runTask, args=[[b'\naer_session_py_20220810.125209.732_192.168.222.129-py-job-20220810.125240.464968_withStores-task-2\x12\nwithStores\x1a\xc0\x01\x08\x02\x12p\x12\x0fROLL_PAIR_CACHE\x1a\x0fer_session_meta"1er_session_py_20220810.125209.732_192.168.222.1290\x03:\x0fBYTESTRING_HASHB\x06PICKLE\x1aH\x08\x06\x10\x02"\x08egg_pair*\x07RUNNING2\x15\n\x0f192.168.222.129\x10\xd9\x8d\x02:\x15\n\x0f192.168.222.129\x10\xf5\xcb'], len=1], kwargs=[***, len=0])
Traceback (most recent call last):
  File "/home/app/workspace/Eggroll_deploy_0/python/eggroll/core/client.py", line 84, in sync_send
    response = _command_stub.call(request.to_proto())
  File "/home/app/.venv_eggroll/lib/python3.6/site-packages/grpc/_channel.py", line 604, in __call__
    return _end_unary_response_blocking(state, call, False, None)
  File "/home/app/.venv_eggroll/lib/python3.6/site-packages/grpc/_channel.py", line 506, in _end_unary_response_blocking
    raise _Rendezvous(state, None, None, deadline)
grpc._channel._Rendezvous: <_Rendezvous of RPC that terminated with:
	status = StatusCode.UNKNOWN
	details = "Exception calling application: 

==== detail start, at 20220810.125240.482 ====
Traceback (most recent call last):
  File "/home/app/workspace/Eggroll_deploy_0/python/eggroll/core/utils.py", line 187, in wrapper
    return func(*args, **kw)
  File "/home/app/workspace/Eggroll_deploy_0/python/eggroll/roll_pair/egg_pair.py", line 690, in run_task
    value=self.functor_serdes.serialize(f(task)))
  File "/home/app/workspace/Eggroll_deploy_0/python/eggroll/roll_pair/test/test_roll_pair.py", line 80, in get_eggs
    eggs = input_adapter.get('eggs')
  File "/home/app/workspace/Eggroll_deploy_0/python/eggroll/core/pair_store/adapter.py", line 190, in get
    return self.data[key]
KeyError: 'eggs'

During handling of the above exception, another exception occurred:

Traceback (most recent call last):
  File "/home/app/workspace/Eggroll_deploy_0/python/eggroll/core/utils.py", line 187, in wrapper
    return func(*args, **kw)
  File "/home/app/workspace/Eggroll_deploy_0/python/eggroll/core/command/command_service.py", line 33, in call
    kwargs=getattr(command_request, '_kwargs'))
  File "/home/app/workspace/Eggroll_deploy_0/python/eggroll/core/command/command_router.py", line 94, in dispatch
    raise e
  File "/home/app/workspace/Eggroll_deploy_0/python/eggroll/core/command/command_router.py", line 91, in dispatch
    call_result = _method(_instance, *deserialized_args)
  File "/home/app/workspace/Eggroll_deploy_0/python/eggroll/core/utils.py", line 194, in wrapper
    raise RuntimeError(msg)
RuntimeError: 

==== detail start, at 20220810.125240.481 ====
Traceback (most recent call last):
  File "/home/app/workspace/Eggroll_deploy_0/python/eggroll/core/utils.py", line 187, in wrapper
    return func(*args, **kw)
  File "/home/app/workspace/Eggroll_deploy_0/python/eggroll/roll_pair/egg_pair.py", line 690, in run_task
    value=self.functor_serdes.serialize(f(task)))
  File "/home/app/workspace/Eggroll_deploy_0/python/eggroll/roll_pair/test/test_roll_pair.py", line 80, in get_eggs
    eggs = input_adapter.get('eggs')
  File "/home/app/workspace/Eggroll_deploy_0/python/eggroll/core/pair_store/adapter.py", line 190, in get
    return self.data[key]
KeyError: 'eggs'

==== detail end ====



==== detail end ====

"
	debug_error_string = "{"created":"@1660107160.483955132","description":"Error received from peer ipv4:192.168.222.129:34521","file":"src/core/lib/surface/call.cc","file_line":1055,"grpc_message":"Exception calling application: \n\n==== detail start, at 20220810.125240.482 ====\nTraceback (most recent call last):\n  File "/home/app/workspace/Eggroll_deploy_0/python/eggroll/core/utils.py", line 187, in wrapper\n    return func(*args, **kw)\n  File "/home/app/workspace/Eggroll_deploy_0/python/eggroll/roll_pair/egg_pair.py", line 690, in run_task\n    value=self.functor_serdes.serialize(f(task)))\n  File "/home/app/workspace/Eggroll_deploy_0/python/eggroll/roll_pair/test/test_roll_pair.py", line 80, in get_eggs\n    eggs = input_adapter.get('eggs')\n  File "/home/app/workspace/Eggroll_deploy_0/python/eggroll/core/pair_store/adapter.py", line 190, in get\n    return self.data[key]\nKeyError: 'eggs'\n\nDuring handling of the above exception, another exception occurred:\n\nTraceback (most recent call last):\n  File "/home/app/workspace/Eggroll_deploy_0/python/eggroll/core/utils.py", line 187, in wrapper\n    return func(*args, **kw)\n  File "/home/app/workspace/Eggroll_deploy_0/python/eggroll/core/command/command_service.py", line 33, in call\n    kwargs=getattr(command_request, '_kwargs'))\n  File "/home/app/workspace/Eggroll_deploy_0/python/eggroll/core/command/command_router.py", line 94, in dispatch\n    raise e\n  File "/home/app/workspace/Eggroll_deploy_0/python/eggroll/core/command/command_router.py", line 91, in dispatch\n    call_result = _method(_instance, *deserialized_args)\n  File "/home/app/workspace/Eggroll_deploy_0/python/eggroll/core/utils.py", line 194, in wrapper\n    raise RuntimeError(msg)\nRuntimeError: \n\n==== detail start, at 20220810.125240.481 ====\nTraceback (most recent call last):\n  File "/home/app/workspace/Eggroll_deploy_0/python/eggroll/core/utils.py", line 187, in wrapper\n    return func(*args, **kw)\n  File "/home/app/workspace/Eggroll_deploy_0/python/eggroll/roll_pair/egg_pair.py", line 690, in run_task\n    value=self.functor_serdes.serialize(f(task)))\n  File "/home/app/workspace/Eggroll_deploy_0/python/eggroll/roll_pair/test/test_roll_pair.py", line 80, in get_eggs\n    eggs = input_adapter.get('eggs')\n  File "/home/app/workspace/Eggroll_deploy_0/python/eggroll/core/pair_store/adapter.py", line 190, in get\n    return self.data[key]\nKeyError: 'eggs'\n\n==== detail end ====\n\n\n\n==== detail end ====\n\n","grpc_status":2}"
>
