/home/app/workspace/Eggroll_deploy/data
k:e, v:5
k:g, v:6
lambda ret:[('B_0', 5), ('B_1', 6), ('C_0', 6), ('C_1', 7)]


==== detail start, at 20220808.183554.440 ====
Traceback (most recent call last):
  File "/home/app/workspace/Eggroll_deploy/python/eggroll/core/utils.py", line 187, in wrapper
    return func(*args, **kw)
  File "/home/app/workspace/Eggroll_deploy/python/eggroll/roll_pair/egg_pair.py", line 690, in run_task
    value=self.functor_serdes.serialize(f(task)))
  File "/home/app/workspace/Eggroll_deploy/python/eggroll/roll_pair/test/test_roll_pair.py", line 80, in get_eggs
    eggs = input_adapter.get('eggs')
  File "/home/app/workspace/Eggroll_deploy/python/eggroll/core/pair_store/adapter.py", line 190, in get
    return self.data[key]
KeyError: 'eggs'

==== detail end ====




==== detail start, at 20220808.183554.442 ====
Traceback (most recent call last):
  File "/home/app/workspace/Eggroll_deploy/python/eggroll/core/utils.py", line 187, in wrapper
    return func(*args, **kw)
  File "/home/app/workspace/Eggroll_deploy/python/eggroll/roll_pair/egg_pair.py", line 690, in run_task
    value=self.functor_serdes.serialize(f(task)))
  File "/home/app/workspace/Eggroll_deploy/python/eggroll/roll_pair/test/test_roll_pair.py", line 80, in get_eggs
    eggs = input_adapter.get('eggs')
  File "/home/app/workspace/Eggroll_deploy/python/eggroll/core/pair_store/adapter.py", line 190, in get
    return self.data[key]
KeyError: 'eggs'

During handling of the above exception, another exception occurred:

Traceback (most recent call last):
  File "/home/app/workspace/Eggroll_deploy/python/eggroll/core/utils.py", line 187, in wrapper
    return func(*args, **kw)
  File "/home/app/workspace/Eggroll_deploy/python/eggroll/core/command/command_service.py", line 33, in call
    kwargs=getattr(command_request, '_kwargs'))
  File "/home/app/workspace/Eggroll_deploy/python/eggroll/core/command/command_router.py", line 94, in dispatch
    raise e
  File "/home/app/workspace/Eggroll_deploy/python/eggroll/core/command/command_router.py", line 91, in dispatch
    call_result = _method(_instance, *deserialized_args)
  File "/home/app/workspace/Eggroll_deploy/python/eggroll/core/utils.py", line 194, in wrapper
    raise RuntimeError(msg)
RuntimeError: 

==== detail start, at 20220808.183554.440 ====
Traceback (most recent call last):
  File "/home/app/workspace/Eggroll_deploy/python/eggroll/core/utils.py", line 187, in wrapper
    return func(*args, **kw)
  File "/home/app/workspace/Eggroll_deploy/python/eggroll/roll_pair/egg_pair.py", line 690, in run_task
    value=self.functor_serdes.serialize(f(task)))
  File "/home/app/workspace/Eggroll_deploy/python/eggroll/roll_pair/test/test_roll_pair.py", line 80, in get_eggs
    eggs = input_adapter.get('eggs')
  File "/home/app/workspace/Eggroll_deploy/python/eggroll/core/pair_store/adapter.py", line 190, in get
    return self.data[key]
KeyError: 'eggs'

==== detail end ====



==== detail end ====


