(.venv_eggroll) app@ubuntu:~/workspace/sequoia-demo/python/fate_script2/test$ python3.6 -m unittest test_hetero_logistic_regression_rtw.TestHeteroLREncryptedRTW
static conf path: /home/app/workspace/Eggroll_deploy_0/conf/eggroll.properties
EEE
======================================================================
ERROR: test_fit_vlr_fed_local_to_local (test_hetero_logistic_regression_rtw.TestHeteroLREncryptedRTW)
----------------------------------------------------------------------
Traceback (most recent call last):
  File "/home/app/workspace/Eggroll/python/eggroll/core/client.py", line 84, in sync_send
    response = _command_stub.call(request.to_proto())
  File "/home/app/.venv_eggroll/lib/python3.6/site-packages/grpc/_channel.py", line 604, in __call__
    return _end_unary_response_blocking(state, call, False, None)
  File "/home/app/.venv_eggroll/lib/python3.6/site-packages/grpc/_channel.py", line 506, in _end_unary_response_blocking
    raise _Rendezvous(state, None, None, deadline)
grpc._channel._Rendezvous: <_Rendezvous of RPC that terminated with:
        status = StatusCode.UNAVAILABLE
        details = "failed to connect to all addresses"
        debug_error_string = "{"created":"@1660108712.211246083","description":"Failed to pick subchannel","file":"src/core/ext/filters/client_channel/client_channel.cc","file_line":3876,"referenced_errors":[{"created":"@1660108712.211238063","description":"failed to connect to all addresses","file":"src/core/ext/filters/client_channel/lb_policy/pick_first/pick_first.cc","file_line":395,"grpc_status":14}]}"
>

During handling of the above exception, another exception occurred:

Traceback (most recent call last):
  File "/home/app/workspace/sequoia-demo/python/fate_script2/test/test_hetero_logistic_regression_rtw.py", line 160, in test_fit_vlr_fed_local_to_local
    self._run_lr_with_er_fed_router(guest_distributed=False, host_distributed=False)
  File "/home/app/workspace/sequoia-demo/python/fate_script2/test/test_hetero_logistic_regression_rtw.py", line 104, in _run_lr_with_er_fed_router
    transfer_port=20004, props_file=guest_props_file)
  File "/home/app/workspace/Eggroll/python/eggroll/roll_site/test/roll_site_test_asset.py", line 102, in get_debug_test_context
    session_id='_'.join([roll_site_session_id, role, str(self_party_id)]))
  File "/home/app/workspace/Eggroll/python/eggroll/roll_pair/test/roll_pair_test_assets.py", line 57, in get_debug_test_context
    context = RollPairContext(session)
  File "/home/app/workspace/Eggroll/python/eggroll/roll_pair/roll_pair.py", line 88, in __init__
    self.session_default_rp.with_stores(func=_broadcast_eggs)
  File "/home/app/workspace/Eggroll/python/eggroll/core/aspects.py", line 30, in wrapper
    result = func(*args, **kwargs)
  File "/home/app/workspace/Eggroll/python/eggroll/roll_pair/roll_pair.py", line 1152, in with_stores
    ret_pair = future.result()[0]
  File "/usr/lib/python3.6/concurrent/futures/_base.py", line 432, in result
    return self.__get_result()
  File "/usr/lib/python3.6/concurrent/futures/_base.py", line 384, in __get_result
    raise self._exception
  File "/home/app/workspace/Eggroll/python/eggroll/core/datastructure/threadpool.py", line 51, in run
    result = self.fn(*self.args, **self.kwargs)
  File "/home/app/workspace/Eggroll/python/eggroll/core/client.py", line 97, in sync_send
    raise CommandCallError(command_uri, endpoint, e)
eggroll.core.client.CommandCallError: ('Failed to call command: CommandURI(_uri=v1/egg-pair/runTask) to endpoint: 127.0.0.1:20003, caused by: ', <_Rendezvous of RPC that terminated with:
        status = StatusCode.UNAVAILABLE
        details = "failed to connect to all addresses"
        debug_error_string = "{"created":"@1660108712.211246083","description":"Failed to pick subchannel","file":"src/core/ext/filters/client_channel/client_channel.cc","file_line":3876,"referenced_errors":[{"created":"@1660108712.211238063","description":"failed to connect to all addresses","file":"src/core/ext/filters/client_channel/lb_policy/pick_first/pick_first.cc","file_line":395,"grpc_status":14}]}"
>)

======================================================================
ERROR: test_fit_vlr_fed_rtw_to_local (test_hetero_logistic_regression_rtw.TestHeteroLREncryptedRTW)
----------------------------------------------------------------------
Traceback (most recent call last):
  File "/home/app/workspace/Eggroll/python/eggroll/core/client.py", line 84, in sync_send
    response = _command_stub.call(request.to_proto())
  File "/home/app/.venv_eggroll/lib/python3.6/site-packages/grpc/_channel.py", line 604, in __call__
    return _end_unary_response_blocking(state, call, False, None)
  File "/home/app/.venv_eggroll/lib/python3.6/site-packages/grpc/_channel.py", line 506, in _end_unary_response_blocking
    raise _Rendezvous(state, None, None, deadline)
grpc._channel._Rendezvous: <_Rendezvous of RPC that terminated with:
        status = StatusCode.UNAVAILABLE
        details = "failed to connect to all addresses"
        debug_error_string = "{"created":"@1660108712.480442047","description":"Failed to pick subchannel","file":"src/core/ext/filters/client_channel/client_channel.cc","file_line":3876,"referenced_errors":[{"created":"@1660108712.211238063","description":"failed to connect to all addresses","file":"src/core/ext/filters/client_channel/lb_policy/pick_first/pick_first.cc","file_line":395,"grpc_status":14}]}"
>

During handling of the above exception, another exception occurred:

Traceback (most recent call last):
  File "/home/app/workspace/sequoia-demo/python/fate_script2/test/test_hetero_logistic_regression_rtw.py", line 157, in test_fit_vlr_fed_rtw_to_local
    self._run_lr_with_er_fed_router(guest_distributed=True, host_distributed=False)
  File "/home/app/workspace/sequoia-demo/python/fate_script2/test/test_hetero_logistic_regression_rtw.py", line 104, in _run_lr_with_er_fed_router
    transfer_port=20004, props_file=guest_props_file)
  File "/home/app/workspace/Eggroll/python/eggroll/roll_site/test/roll_site_test_asset.py", line 102, in get_debug_test_context
    session_id='_'.join([roll_site_session_id, role, str(self_party_id)]))
  File "/home/app/workspace/Eggroll/python/eggroll/roll_pair/test/roll_pair_test_assets.py", line 57, in get_debug_test_context
    context = RollPairContext(session)
  File "/home/app/workspace/Eggroll/python/eggroll/roll_pair/roll_pair.py", line 88, in __init__
    self.session_default_rp.with_stores(func=_broadcast_eggs)
  File "/home/app/workspace/Eggroll/python/eggroll/core/aspects.py", line 30, in wrapper
    result = func(*args, **kwargs)
  File "/home/app/workspace/Eggroll/python/eggroll/roll_pair/roll_pair.py", line 1152, in with_stores
    ret_pair = future.result()[0]
  File "/usr/lib/python3.6/concurrent/futures/_base.py", line 432, in result
    return self.__get_result()
  File "/usr/lib/python3.6/concurrent/futures/_base.py", line 384, in __get_result
    raise self._exception
  File "/home/app/workspace/Eggroll/python/eggroll/core/datastructure/threadpool.py", line 51, in run
    result = self.fn(*self.args, **self.kwargs)
  File "/home/app/workspace/Eggroll/python/eggroll/core/client.py", line 97, in sync_send
    raise CommandCallError(command_uri, endpoint, e)
eggroll.core.client.CommandCallError: ('Failed to call command: CommandURI(_uri=v1/egg-pair/runTask) to endpoint: 127.0.0.1:20003, caused by: ', <_Rendezvous of RPC that terminated with:
        status = StatusCode.UNAVAILABLE
        details = "failed to connect to all addresses"
        debug_error_string = "{"created":"@1660108712.480442047","description":"Failed to pick subchannel","file":"src/core/ext/filters/client_channel/client_channel.cc","file_line":3876,"referenced_errors":[{"created":"@1660108712.211238063","description":"failed to connect to all addresses","file":"src/core/ext/filters/client_channel/lb_policy/pick_first/pick_first.cc","file_line":395,"grpc_status":14}]}"
>)

======================================================================
ERROR: test_fit_vlr_fed_rtw_to_rtw (test_hetero_logistic_regression_rtw.TestHeteroLREncryptedRTW)
----------------------------------------------------------------------
Traceback (most recent call last):
  File "/home/app/workspace/Eggroll/python/eggroll/core/client.py", line 84, in sync_send
    response = _command_stub.call(request.to_proto())
  File "/home/app/.venv_eggroll/lib/python3.6/site-packages/grpc/_channel.py", line 604, in __call__
    return _end_unary_response_blocking(state, call, False, None)
  File "/home/app/.venv_eggroll/lib/python3.6/site-packages/grpc/_channel.py", line 506, in _end_unary_response_blocking
    raise _Rendezvous(state, None, None, deadline)
grpc._channel._Rendezvous: <_Rendezvous of RPC that terminated with:
        status = StatusCode.UNAVAILABLE
        details = "failed to connect to all addresses"
        debug_error_string = "{"created":"@1660108712.707308876","description":"Failed to pick subchannel","file":"src/core/ext/filters/client_channel/client_channel.cc","file_line":3876,"referenced_errors":[{"created":"@1660108712.211238063","description":"failed to connect to all addresses","file":"src/core/ext/filters/client_channel/lb_policy/pick_first/pick_first.cc","file_line":395,"grpc_status":14}]}"
>

During handling of the above exception, another exception occurred:

Traceback (most recent call last):
  File "/home/app/workspace/sequoia-demo/python/fate_script2/test/test_hetero_logistic_regression_rtw.py", line 154, in test_fit_vlr_fed_rtw_to_rtw
    self._run_lr_with_er_fed_router(guest_distributed=True, host_distributed=True)
  File "/home/app/workspace/sequoia-demo/python/fate_script2/test/test_hetero_logistic_regression_rtw.py", line 104, in _run_lr_with_er_fed_router
    transfer_port=20004, props_file=guest_props_file)
  File "/home/app/workspace/Eggroll/python/eggroll/roll_site/test/roll_site_test_asset.py", line 102, in get_debug_test_context
    session_id='_'.join([roll_site_session_id, role, str(self_party_id)]))
  File "/home/app/workspace/Eggroll/python/eggroll/roll_pair/test/roll_pair_test_assets.py", line 57, in get_debug_test_context
    context = RollPairContext(session)
  File "/home/app/workspace/Eggroll/python/eggroll/roll_pair/roll_pair.py", line 88, in __init__
    self.session_default_rp.with_stores(func=_broadcast_eggs)
  File "/home/app/workspace/Eggroll/python/eggroll/core/aspects.py", line 30, in wrapper
    result = func(*args, **kwargs)
  File "/home/app/workspace/Eggroll/python/eggroll/roll_pair/roll_pair.py", line 1152, in with_stores
    ret_pair = future.result()[0]
  File "/usr/lib/python3.6/concurrent/futures/_base.py", line 432, in result
    return self.__get_result()
  File "/usr/lib/python3.6/concurrent/futures/_base.py", line 384, in __get_result
    raise self._exception
  File "/home/app/workspace/Eggroll/python/eggroll/core/datastructure/threadpool.py", line 51, in run
    result = self.fn(*self.args, **self.kwargs)
  File "/home/app/workspace/Eggroll/python/eggroll/core/client.py", line 97, in sync_send
    raise CommandCallError(command_uri, endpoint, e)
eggroll.core.client.CommandCallError: ('Failed to call command: CommandURI(_uri=v1/egg-pair/runTask) to endpoint: 127.0.0.1:20003, caused by: ', <_Rendezvous of RPC that terminated with:
        status = StatusCode.UNAVAILABLE
        details = "failed to connect to all addresses"
        debug_error_string = "{"created":"@1660108712.707308876","description":"Failed to pick subchannel","file":"src/core/ext/filters/client_channel/client_channel.cc","file_line":3876,"referenced_errors":[{"created":"@1660108712.211238063","description":"failed to connect to all addresses","file":"src/core/ext/filters/client_channel/lb_policy/pick_first/pick_first.cc","file_line":395,"grpc_status":14}]}"
>)

----------------------------------------------------------------------
Ran 3 tests in 1.584s

FAILED (errors=3)
(.venv_eggroll) app@ubuntu:~/workspace/sequoia-demo/python/fate_script2/test$